.....F......
======================================================================
FAIL: test_number_arguments (__main__.TestPractica3)
----------------------------------------------------------------------
Traceback (most recent call last):
  File "/home/as/tests_practicas_AS/tests/./test_practica3.py", line 126, in test_number_arguments
    self.child.expect_exact('Numero incorrecto de parametros\r\n')
pexpect.exceptions.EOF: End Of File (EOF). Exception style platform.
<pexpect.pty_spawn.spawn object at 0x7f5e59be3fd0>
command: /usr/bin/sudo
args: [b'/usr/bin/sudo', b'/bin/bash', b'/home/as/tests_practicas_AS/practica_3/practica_3.sh', b'-a', b'/home/as/tests_practicas_AS/tests/correct_user_list.txt', b'extra_arg']
buffer (last 100 chars): ''
before (last 100 chars): 'Louis Poizin ha sido creado\r\nRadia Perlman ha sido creado\r\nJean Bartik ha sido creado\r\n'
after: <class 'pexpect.exceptions.EOF'>
match: None
match_index: None
exitstatus: None
flag_eof: True
pid: 2305
child_fd: 5
closed: False
timeout: 30
delimiter: <class 'pexpect.exceptions.EOF'>
logfile: None
logfile_read: None
logfile_send: None
maxread: 2000
ignorecase: False
searchwindowsize: None
delaybeforesend: 0.05
delayafterclose: 0.1
delayafterterminate: 0.1
searcher: searcher_string:
    0: 'Numero incorrecto de parametros\r\n'

During handling of the above exception, another exception occurred:

Traceback (most recent call last):
  File "/home/as/tests_practicas_AS/tests/./test_practica3.py", line 128, in test_number_arguments
    self.assertTrue(False)
AssertionError: False is not true

----------------------------------------------------------------------
Ran 12 tests in 3.538s

FAILED (failures=1)
