FF.
======================================================================
FAIL: test_connectivity (__main__.TestPractica4)
Check whether the expected nodes are alive
----------------------------------------------------------------------
Traceback (most recent call last):
  File "/home/as/tests_practicas_AS/tests/./test_practica4.py", line 48, in test_connectivity
    s.login(ip, "as", ssh_key="/home/as/.ssh/id_as_ed25519")
pexpect.pxssh.ExceptionPxssh: Could not establish connection to host

During handling of the above exception, another exception occurred:

Traceback (most recent call last):
  File "/home/as/tests_practicas_AS/tests/./test_practica4.py", line 55, in test_connectivity
    self.assertTrue(False)
AssertionError: False is not true

======================================================================
FAIL: test_no_root (__main__.TestPractica4)
find PermitRootLogin no in /etc/sshd_config
----------------------------------------------------------------------
Traceback (most recent call last):
  File "/home/as/tests_practicas_AS/tests/./test_practica4.py", line 69, in test_no_root
    s.login(ip, "as", ssh_key="/home/as/.ssh/id_as_ed25519")
pexpect.pxssh.ExceptionPxssh: Could not establish connection to host

During handling of the above exception, another exception occurred:

Traceback (most recent call last):
  File "/home/as/tests_practicas_AS/tests/./test_practica4.py", line 78, in test_no_root
    self.assertTrue(False)
AssertionError: False is not true

----------------------------------------------------------------------
Ran 3 tests in 0.377s

FAILED (failures=2)
Login to 192.168.56.11 failed!, error: Could not establish connection to host
